<?xml version="1.0" ?>
<!-- =================================================================================== -->
<!-- |    This document was autogenerated by xacro from pico3.xacro                    | -->
<!-- |    EDITING THIS FILE BY HAND IS NOT RECOMMENDED                                 | -->
<!-- =================================================================================== -->
<robot name="pico3">
  <material name="silver_default">
    <color rgba="0.700 0.700 0.700 1.000"/>
  </material>
  <material name="_">
    <color rgba="0.9607843137254902 0.9607843137254902 0.9647058823529412 1.0"/>
  </material>
  <transmission name="rev18_tran">
    <type>transmission_interface/SimpleTransmission</type>
    <joint name="rev18">
      <hardwareInterface>hardware_interface/EffortJointInterface</hardwareInterface>
    </joint>
    <actuator name="rev18_actr">
      <hardwareInterface>hardware_interface/EffortJointInterface</hardwareInterface>
      <mechanicalReduction>1</mechanicalReduction>
    </actuator>
  </transmission>
  <transmission name="rev19_tran">
    <type>transmission_interface/SimpleTransmission</type>
    <joint name="rev19">
      <hardwareInterface>hardware_interface/EffortJointInterface</hardwareInterface>
    </joint>
    <actuator name="rev19_actr">
      <hardwareInterface>hardware_interface/EffortJointInterface</hardwareInterface>
      <mechanicalReduction>1</mechanicalReduction>
    </actuator>
  </transmission>
  <link name="base_link">
    <inertial>
      <origin rpy="0 0 0" xyz="-0.01732832550573724 -0.028076387363741385 0.008428795579960836"/>
      <mass value="0.25793695054434457"/>
      <inertia ixx="0.000109" ixy="-1e-06" ixz="-0.0" iyy="0.000115" iyz="0.0" izz="0.000141"/>
    </inertial>
    <visual>
      <origin rpy="0 0 0" xyz="0 0 0"/>
      <geometry>
        <mesh filename="package://pico3_description/meshes/base_link.stl" scale="0.001 0.001 0.001"/>
      </geometry>
      <material name="_"/>
    </visual>
    <collision>
      <origin rpy="0 0 0" xyz="0 0 0"/>
      <geometry>
        <mesh filename="package://pico3_description/meshes/base_link.stl" scale="0.001 0.001 0.001"/>
      </geometry>
    </collision>
  </link>
  <link name="44mm_wheel_v1_1_1_1">
    <inertial>
      <origin rpy="0 0 0" xyz="2.0004102618792485e-05 0.004777000743186696 2.4180340919379914e-05"/>
      <mass value="0.014367207321355414"/>
      <inertia ixx="3e-06" ixy="0.0" ixz="0.0" iyy="6e-06" iyz="0.0" izz="3e-06"/>
    </inertial>
    <visual>
      <origin rpy="0 0 0" xyz="0.016588 0.06586 -0.010064"/>
      <geometry>
        <mesh filename="package://pico3_description/meshes/44mm_wheel_v1_1_1_1.stl" scale="0.001 0.001 0.001"/>
      </geometry>
      <material name="_"/>
    </visual>
    <collision>
      <origin rpy="0 0 0" xyz="0.016588 0.06586 -0.010064"/>
      <geometry>
        <mesh filename="package://pico3_description/meshes/44mm_wheel_v1_1_1_1.stl" scale="0.001 0.001 0.001"/>
      </geometry>
    </collision>
  </link>
  <link name="44mm_wheel_v1__1__1_1_1">
    <inertial>
      <origin rpy="0 0 0" xyz="0.00011503190831341908 -0.004751453878412586 1.502109863796633e-05"/>
      <mass value="0.014316395337638727"/>
      <inertia ixx="3e-06" ixy="-0.0" ixz="0.0" iyy="6e-06" iyz="-0.0" izz="3e-06"/>
    </inertial>
    <visual>
      <origin rpy="0 0 0" xyz="0.016639 -0.009495 -0.010108"/>
      <geometry>
        <mesh filename="package://pico3_description/meshes/44mm_wheel_v1__1__1_1_1.stl" scale="0.001 0.001 0.001"/>
      </geometry>
      <material name="_"/>
    </visual>
    <collision>
      <origin rpy="0 0 0" xyz="0.016639 -0.009495 -0.010108"/>
      <geometry>
        <mesh filename="package://pico3_description/meshes/44mm_wheel_v1__1__1_1_1.stl" scale="0.001 0.001 0.001"/>
      </geometry>
    </collision>
  </link>
  <joint name="rev18" type="continuous">
    <origin rpy="0 0 0" xyz="-0.016588 -0.06586 0.010064"/>
    <parent link="base_link"/>
    <child link="44mm_wheel_v1_1_1_1"/>
    <axis xyz="0.0 -1.0 -0.0"/>
  </joint>
  <joint name="rev19" type="continuous">
    <origin rpy="0 0 0" xyz="-0.016639 0.009495 0.010108"/>
    <parent link="base_link"/>
    <child link="44mm_wheel_v1__1__1_1_1"/>
    <axis xyz="0.0 1.0 0.0"/>
  </joint>
</robot>
