<?xml version="1.0" ?>
<robot name="pico3" xmlns:xacro="http://www.ros.org/wiki/xacro">

<xacro:include filename="$(find pico3_description)/urdf/materials.xacro" />
<xacro:include filename="$(find pico3_description)/urdf/pico3.trans" />
<link name="base_link"/>
<link name="body">
  <inertial>
    <origin xyz="0 0 0" rpy="0 0 0"/>
    <mass value="0.25793695054434457"/>
    <inertia ixx="0.000109" iyy="0.000115" izz="0.000141" ixy="-1e-06" iyz="0.0" ixz="-0.0"/>
  </inertial>
  <visual>
    <origin xyz="0.0168 0.0282 -0.0085" rpy="0 0 0"/>
    <geometry>
      <mesh filename="package://pico3_description/meshes/base_link.stl" scale="0.001 0.001 0.001"/>
    </geometry>
    <material name="_"/>
  </visual>
  <collision>
    <origin xyz="0 0 0" rpy="0 0 0"/>
    <geometry>
      <mesh filename="package://pico3_description/meshes/base_link.stl" scale="0.001 0.001 0.001"/>
    </geometry>
  </collision>
</link>

<link name="44mm_wheel_v1_1_1_1">
  <inertial>
    <origin xyz="0 0 0" rpy="0 0 0"/>
    <mass value="0.014367207321355414"/>
    <inertia ixx="3e-06" iyy="6e-06" izz="3e-06" ixy="0.0" iyz="0.0" ixz="0.0"/>
  </inertial>
  <visual>
    <origin xyz="0.016588 0.06586 -0.010064" rpy="0 0 0"/>
    <geometry>
      <mesh filename="package://pico3_description/meshes/44mm_wheel_v1_1_1_1.stl" scale="0.001 0.001 0.001"/>
    </geometry>
    <material name="_"/>
  </visual>
  <collision>
    <origin xyz="0 0 0" rpy="0 0 0"/>
    <geometry>
      <mesh filename="package://pico3_description/meshes/44mm_wheel_v1_1_1_1.stl" scale="0.001 0.001 0.001"/>
    </geometry>
  </collision>
</link>

<link name="44mm_wheel_v1__1__1_1_1">
  <inertial>
    <origin xyz="0.0 0.0 0.0" rpy="0 0 0"/>
    <mass value="0.014316395337638727"/>
    <inertia ixx="3e-06" iyy="6e-06" izz="3e-06" ixy="-0.0" iyz="-0.0" ixz="0.0"/>
  </inertial>
  <visual>
    <origin xyz="0.016639 -0.009495 -0.010108" rpy="0 0 0"/>
    <geometry>
      <mesh filename="package://pico3_description/meshes/44mm_wheel_v1__1__1_1_1.stl" scale="0.001 0.001 0.001"/>
    </geometry>
    <material name="_"/>
  </visual>
  <collision>
    <origin xyz="0.0 0.0 0.0" rpy="0 0 0"/>
    <geometry>
      <mesh filename="package://pico3_description/meshes/44mm_wheel_v1__1__1_1_1.stl" scale="0.001 0.001 0.001"/>
    </geometry>
  </collision>
</link>


<joint name="body_joint" type="fixed">
  <parent link="base_link" />
  <child link="body"/>
  <origin xyz="0 0 0.0235" rpy="0 0 0" />
</joint>

<joint name="rev18" type="continuous">
  <origin xyz="0.000 -0.037 0.0235" rpy="0 0 0"/>
  <parent link="base_link"/>
  <child link="44mm_wheel_v1_1_1_1"/>
  <axis xyz="0.0 -1.0 -0.0"/>
</joint>

<joint name="rev19" type="continuous">
  <origin xyz="0.000 0.037 0.0235" rpy="0 0 0"/>
  <parent link="base_link"/>
  <child link="44mm_wheel_v1__1__1_1_1"/>
  <axis xyz="0.0 1.0 0.0"/>
</joint>

</robot>
