<?xml version="1.0" ?>
<!-- =================================================================================== -->
<!-- |    This document was autogenerated by xacro from robot.urdf.xacro               | -->
<!-- |    EDITING THIS FILE BY HAND IS NOT RECOMMENDED                                 | -->
<!-- =================================================================================== -->
<robot name="SimpleMouse">
  <link name="base_link"/>
  <link name="body">
    <visual>
      <geometry>
        <box size="0.07 0.13 0.055"/>
      </geometry>
    </visual>
  </link>
  <joint name="body_joint" type="fixed">
    <parent link="base_link"/>
    <child link="body"/>
    <origin rpy="0 0 0" xyz="0 0 0.0275"/>
  </joint>
  <link name="wheel_r">
    <visual>
      <geometry>
        <cylinder length="0.008" radius="0.024"/>
      </geometry>
    </visual>
  </link>
  <joint name="wheel_r_joint" type="continuous">
    <parent link="body"/>
    <child link="wheel_r"/>
    <origin rpy="0 1.5707963267948966 0" xyz="0.04 0 -0.005500000000000001"/>
    <axis xyz="0 0 1"/>
    <limit effort="10" velocity="10"/>
    <joint_properties damping="0.0" friction="0.0"/>
  </joint>
  <link name="wheel_l">
    <visual>
      <geometry>
        <cylinder length="0.008" radius="0.024"/>
      </geometry>
    </visual>
  </link>
  <joint name="wheel_l_joint" type="continuous">
    <parent link="body"/>
    <child link="wheel_l"/>
    <origin rpy="0 1.5707963267948966 0" xyz="-0.04 0 -0.005500000000000001"/>
    <axis xyz="0 0 1"/>
    <limit effort="10" velocity="10"/>
    <joint_properties damping="0.0" friction="0.0"/>
  </joint>
</robot>
